Workbook
Name assessment: Dropdown_list!$Q$2:$Q$3
Name Means_transport: Dropdown_list!$C$2:$C$7
Name NFI: 'NFI dimensions'!$C$2:$C$12
Name NFI_ITEMS: 'List of Items'!$B$2:$B$12
Name NFI_ITEMS1: 'NFI dimensions'!$A$2:$A$12
Name Partners: Dropdown_list!$G$2:$G$124
Name Partners_: Dropdown_list!$G$2:$G$194
Name Req_purpose: Dropdown_list!$A$2:$A$4
Name Shelter: 'NFI dimensions'!$C$14:$C$22
Name SHELTER_ITEMS: 'List of Items'!$B$13:$B$21
Name Shelter_items1: 'NFI dimensions'!$A$13:$A$22
Name State_col: Dropdown_list!$M$2:$M$80
Name State_start_col: Dropdown_list!$M$2
Name States: Dropdown_list!$J$2:$J$12
Name Yes_no: Dropdown_list!$I$1:$I$2

Sheet request form
D1: Shelter/NFI Pipeline REQUEST FORM
A3: Instructions: Please use this form for all requests for items from Shelter/NFI Cluster Common Pipeline 1. All fields indicates with asterik (*) are mandatory. Please ensure to complete it before sending to the Pipeline Team 2. Please send your Pipeline Request to: scsouthsudan-pipeline@googlegroups.com | G3: For IOM Juba Use Only
G4: Request Number: (to be filled by the Pipeline Team)
A8: Section 1 - Requester Information | J8: Section 2 - Request Information - (to be filled by the Pipeline Team)
A9: Date* | J9: Date of Request
A10: Requesting Organization* | J10: Date of Approval
A11: Name of Requestor* | J11: Purpose of request | K11: Prepositioning | L11: Immediate Distribution
A12: Position* | J12: Means of Transport | L12: Road
A13: Email* | J13: Transport from | M13: To
A14: Phone* | J14: Location of Storage/Warehouse
A15: Other Contact Details
A17: Section 3 - Consignee Information
A18: Consignee Name* | J18: Click here to see the available stock in pipeline!
A19: Consignee Mobile Number*
A20: Consignee e-mail address*
A22: Section 4. Details of items requested
A23: Items | B23: Item Code | D23: Quantity (pieces)* | E23: Quantity (packing unit) | H23: Weight (KGs) | I23: Volume (M3) | K23: Unit Value (USD) | L23: Estimated Transport Cost (USD)
A24: NFI
B25: =IFERROR(VLOOKUP(A25,'NFI dimensions'!$A$1:$J$22,3,FALSE),"") | E25: =IF(D25="","",IFERROR(D25/VLOOKUP(A25,'NFI dimensions'!$A$2:$J$22,4,0),"")) | H25: =IFERROR(E25*VLOOKUP(A25,'NFI dimensions'!$A$2:$J$22,8,FALSE),"") | I25: =IFERROR(E25*VLOOKUP(A25,'NFI dimensions'!$A$2:$J$22,9,FALSE),"") | K25: =IFERROR(D25*VLOOKUP(A25,'NFI dimensions'!$A$2:$J$22,10,FALSE),"") | L25: =IFERROR(IF($L$12="",0,IF($L$12="Road",H25/1000*750,IF($L$12="Air",H25/1000*2000))),"")
B26: =IFERROR(VLOOKUP(A26,'NFI dimensions'!$A$1:$J$22,3,FALSE),"") | E26: =IF(D26="","",IFERROR(D26/VLOOKUP(A26,'NFI dimensions'!$A$2:$J$22,4,0),"")) | H26: =IFERROR(E26*VLOOKUP(A26,'NFI dimensions'!$A$2:$J$22,8,FALSE),"") | I26: =IFERROR(E26*VLOOKUP(A26,'NFI dimensions'!$A$2:$J$22,9,FALSE),"") | K26: =IFERROR(D26*VLOOKUP(A26,'NFI dimensions'!$A$2:$J$22,10,FALSE),"") | L26: =IFERROR(IF($L$12="",0,IF($L$12="Road",H26/1000*750,IF($L$12="Air",H26/1000*2000))),"")
B27: =IFERROR(VLOOKUP(A27,'NFI dimensions'!$A$1:$J$22,3,FALSE),"") | E27: =IF(D27="","",IFERROR(D27/VLOOKUP(A27,'NFI dimensions'!$A$2:$J$22,4,0),"")) | H27: =IFERROR(E27*VLOOKUP(A27,'NFI dimensions'!$A$2:$J$22,8,FALSE),"") | I27: =IFERROR(E27*VLOOKUP(A27,'NFI dimensions'!$A$2:$J$22,9,FALSE),"") | K27: =IFERROR(D27*VLOOKUP(A27,'NFI dimensions'!$A$2:$J$22,10,FALSE),"") | L27: =IFERROR(IF($L$12="",0,IF($L$12="Road",H27/1000*750,IF($L$12="Air",H27/1000*2000))),"")
B28: =IFERROR(VLOOKUP(A28,'NFI dimensions'!$A$1:$J$22,3,FALSE),"") | E28: =IF(D28="","",IFERROR(D28/VLOOKUP(A28,'NFI dimensions'!$A$2:$J$22,4,0),"")) | H28: =IFERROR(E28*VLOOKUP(A28,'NFI dimensions'!$A$2:$J$22,8,FALSE),"") | I28: =IFERROR(E28*VLOOKUP(A28,'NFI dimensions'!$A$2:$J$22,9,FALSE),"") | K28: =IFERROR(D28*VLOOKUP(A28,'NFI dimensions'!$A$2:$J$22,10,FALSE),"") | L28: =IFERROR(IF($L$12="",0,IF($L$12="Road",H28/1000*750,IF($L$12="Air",H28/1000*2000))),"")
B29: =IFERROR(VLOOKUP(A29,'NFI dimensions'!$A$1:$J$22,3,FALSE),"") | E29: =IF(D29="","",IFERROR(D29/VLOOKUP(A29,'NFI dimensions'!$A$2:$J$22,4,0),"")) | H29: =IFERROR(E29*VLOOKUP(A29,'NFI dimensions'!$A$2:$J$22,8,FALSE),"") | I29: =IFERROR(E29*VLOOKUP(A29,'NFI dimensions'!$A$2:$J$22,9,FALSE),"") | K29: =IFERROR(D29*VLOOKUP(A29,'NFI dimensions'!$A$2:$J$22,10,FALSE),"") | L29: =IFERROR(IF($L$12="",0,IF($L$12="Road",H29/1000*750,IF($L$12="Air",H29/1000*2000))),"")
B30: =IFERROR(VLOOKUP(A30,'NFI dimensions'!$A$1:$J$22,3,FALSE),"") | E30: =IF(D30="","",IFERROR(D30/VLOOKUP(A30,'NFI dimensions'!$A$2:$J$22,4,0),"")) | H30: =IFERROR(E30*VLOOKUP(A30,'NFI dimensions'!$A$2:$J$22,8,FALSE),"") | I30: =IFERROR(E30*VLOOKUP(A30,'NFI dimensions'!$A$2:$J$22,9,FALSE),"") | K30: =IFERROR(D30*VLOOKUP(A30,'NFI dimensions'!$A$2:$J$22,10,FALSE),"") | L30: =IFERROR(IF($L$12="",0,IF($L$12="Road",H30/1000*750,IF($L$12="Air",H30/1000*2000))),"")
B31: =IFERROR(VLOOKUP(A31,'NFI dimensions'!$A$1:$J$22,3,FALSE),"") | E31: =IF(D31="","",IFERROR(D31/VLOOKUP(A31,'NFI dimensions'!$A$2:$J$22,4,0),"")) | H31: =IFERROR(E31*VLOOKUP(A31,'NFI dimensions'!$A$2:$J$22,8,FALSE),"") | I31: =IFERROR(E31*VLOOKUP(A31,'NFI dimensions'!$A$2:$J$22,9,FALSE),"") | K31: =IFERROR(D31*VLOOKUP(A31,'NFI dimensions'!$A$2:$J$22,10,FALSE),"") | L31: =IFERROR(IF($L$12="",0,IF($L$12="Road",H31/1000*750,IF($L$12="Air",H31/1000*2000))),"")
B32: =IFERROR(VLOOKUP(A32,'NFI dimensions'!$A$1:$J$22,3,FALSE),"") | E32: =IF(D32="","",IFERROR(D32/VLOOKUP(A32,'NFI dimensions'!$A$2:$J$22,4,0),"")) | H32: =IFERROR(E32*VLOOKUP(A32,'NFI dimensions'!$A$2:$J$22,8,FALSE),"") | I32: =IFERROR(E32*VLOOKUP(A32,'NFI dimensions'!$A$2:$J$22,9,FALSE),"") | K32: =IFERROR(D32*VLOOKUP(A32,'NFI dimensions'!$A$2:$J$22,10,FALSE),"") | L32: =IFERROR(IF($L$12="",0,IF($L$12="Road",H32/1000*750,IF($L$12="Air",H32/1000*2000))),"")
B33: =IFERROR(VLOOKUP(A33,'NFI dimensions'!$A$1:$J$22,3,FALSE),"") | E33: =IF(D33="","",IFERROR(D33/VLOOKUP(A33,'NFI dimensions'!$A$2:$J$22,4,0),"")) | H33: =IFERROR(E33*VLOOKUP(A33,'NFI dimensions'!$A$2:$J$22,8,FALSE),"") | I33: =IFERROR(E33*VLOOKUP(A33,'NFI dimensions'!$A$2:$J$22,9,FALSE),"") | K33: =IFERROR(D33*VLOOKUP(A33,'NFI dimensions'!$A$2:$J$22,10,FALSE),"") | L33: =IFERROR(IF($L$12="",0,IF($L$12="Road",H33/1000*750,IF($L$12="Air",H33/1000*2000))),"")
B34: =IFERROR(VLOOKUP(A34,'NFI dimensions'!$A$1:$J$22,3,FALSE),"") | E34: =IF(D34="","",IFERROR(D34/VLOOKUP(A34,'NFI dimensions'!$A$2:$J$22,4,0),"")) | H34: =IFERROR(E34*VLOOKUP(A34,'NFI dimensions'!$A$2:$J$22,8,FALSE),"") | I34: =IFERROR(E34*VLOOKUP(A34,'NFI dimensions'!$A$2:$J$22,9,FALSE),"") | K34: =IFERROR(D34*VLOOKUP(A34,'NFI dimensions'!$A$2:$J$22,10,FALSE),"") | L34: =IFERROR(IF($L$12="",0,IF($L$12="Road",H34/1000*750,IF($L$12="Air",H34/1000*2000))),"")
B35: =IFERROR(VLOOKUP(A35,'NFI dimensions'!$A$1:$J$22,3,FALSE),"") | E35: =IF(D35="","",IFERROR(D35/VLOOKUP(A35,'NFI dimensions'!$A$2:$J$22,4,0),"")) | H35: =IFERROR(E35*VLOOKUP(A35,'NFI dimensions'!$A$2:$J$22,8,FALSE),"") | I35: =IFERROR(E35*VLOOKUP(A35,'NFI dimensions'!$A$2:$J$22,9,FALSE),"") | K35: =IFERROR(D35*VLOOKUP(A35,'NFI dimensions'!$A$2:$J$22,10,FALSE),"") | L35: =IFERROR(IF($L$12="",0,IF($L$12="Road",H35/1000*750,IF($L$12="Air",H35/1000*2000))),"")
B36: =IFERROR(VLOOKUP(A36,'NFI dimensions'!$A$1:$J$22,3,FALSE),"") | E36: =IF(D36="","",IFERROR(D36/VLOOKUP(A36,'NFI dimensions'!$A$2:$J$22,4,0),"")) | H36: =IFERROR(E36*VLOOKUP(A36,'NFI dimensions'!$A$2:$J$22,8,FALSE),"") | I36: =IFERROR(E36*VLOOKUP(A36,'NFI dimensions'!$A$2:$J$22,9,FALSE),"") | K36: =IFERROR(D36*VLOOKUP(A36,'NFI dimensions'!$A$2:$J$22,10,FALSE),"") | L36: =IFERROR(IF($L$12="",0,IF($L$12="Road",H36/1000*750,IF($L$12="Air",H36/1000*2000))),"")
A37: Total NFI Requested
H38: =ROUND(SUM(H25:H36),1) -> 0 | I38: =ROUND(SUM(I25:J36),1) -> 0 | K38: =ROUND(SUM(K25:K36),1) -> 0 | L38: =ROUND(SUM(L25:L36),1) -> 0
A39: Shelter
B40: =IFERROR(VLOOKUP(A40,'NFI dimensions'!A2:J22,3,FALSE),"") | E40: =IF(D40="","",IFERROR(D40/VLOOKUP(A40,'NFI dimensions'!$A$2:$J$22,4,0),"")) | H40: =IFERROR(E40*VLOOKUP(A40,'NFI dimensions'!$A$2:$J$22,8,FALSE),"") | I40: =IFERROR(E40*VLOOKUP(A40,'NFI dimensions'!$A$2:$J$22,9,FALSE),"") | K40: =IFERROR(D40*VLOOKUP(A40,'NFI dimensions'!$A$2:$J$22,10,FALSE),"") | L40: =IFERROR(IF($L$12="",0,IF($L$12="Road",H40/1000*750,IF($L$12="Air",H40/1000*2000))),"")
B41: =IFERROR(VLOOKUP(A41,'NFI dimensions'!A3:J23,3,FALSE),"") | E41: =IF(D41="","",IFERROR(D41/VLOOKUP(A41,'NFI dimensions'!$A$2:$J$22,4,0),"")) | H41: =IFERROR(E41*VLOOKUP(A41,'NFI dimensions'!$A$2:$J$22,8,FALSE),"") | I41: =IFERROR(E41*VLOOKUP(A41,'NFI dimensions'!$A$2:$J$22,9,FALSE),"") | K41: =IFERROR(D41*VLOOKUP(A41,'NFI dimensions'!$A$2:$J$22,10,FALSE),"") | L41: =IFERROR(IF($L$12="",0,IF($L$12="Road",H41/1000*750,IF($L$12="Air",H41/1000*2000))),"")
B42: =IFERROR(VLOOKUP(A42,'NFI dimensions'!A4:J24,3,FALSE),"") | E42: =IF(D42="","",IFERROR(D42/VLOOKUP(A42,'NFI dimensions'!$A$2:$J$22,4,0),"")) | H42: =IFERROR(E42*VLOOKUP(A42,'NFI dimensions'!$A$2:$J$22,8,FALSE),"") | I42: =IFERROR(E42*VLOOKUP(A42,'NFI dimensions'!$A$2:$J$22,9,FALSE),"") | K42: =IFERROR(D42*VLOOKUP(A42,'NFI dimensions'!$A$2:$J$22,10,FALSE),"") | L42: =IFERROR(IF($L$12="",0,IF($L$12="Road",H42/1000*750,IF($L$12="Air",H42/1000*2000))),"")
B43: =IFERROR(VLOOKUP(A43,'NFI dimensions'!A5:J25,3,FALSE),"") | E43: =IF(D43="","",IFERROR(D43/VLOOKUP(A43,'NFI dimensions'!$A$2:$J$22,4,0),"")) | H43: =IFERROR(E43*VLOOKUP(A43,'NFI dimensions'!$A$2:$J$22,8,FALSE),"") | I43: =IFERROR(E43*VLOOKUP(A43,'NFI dimensions'!$A$2:$J$22,9,FALSE),"") | K43: =IFERROR(D43*VLOOKUP(A43,'NFI dimensions'!$A$2:$J$22,10,FALSE),"") | L43: =IFERROR(IF($L$12="",0,IF($L$12="Road",H43/1000*750,IF($L$12="Air",H43/1000*2000))),"")
B44: =IFERROR(VLOOKUP(A44,'NFI dimensions'!A6:J26,3,FALSE),"") | E44: =IF(D44="","",IFERROR(D44/VLOOKUP(A44,'NFI dimensions'!$A$2:$J$22,4,0),"")) | H44: =IFERROR(E44*VLOOKUP(A44,'NFI dimensions'!$A$2:$J$22,8,FALSE),"") | I44: =IFERROR(E44*VLOOKUP(A44,'NFI dimensions'!$A$2:$J$22,9,FALSE),"") | K44: =IFERROR(D44*VLOOKUP(A44,'NFI dimensions'!$A$2:$J$22,10,FALSE),"") | L44: =IFERROR(IF($L$12="",0,IF($L$12="Road",H44/1000*750,IF($L$12="Air",H44/1000*2000))),"")
B45: =IFERROR(VLOOKUP(A45,'NFI dimensions'!A7:J27,3,FALSE),"") | E45: =IF(D45="","",IFERROR(D45/VLOOKUP(A45,'NFI dimensions'!$A$2:$J$22,4,0),"")) | H45: =IFERROR(E45*VLOOKUP(A45,'NFI dimensions'!$A$2:$J$22,8,FALSE),"") | I45: =IFERROR(E45*VLOOKUP(A45,'NFI dimensions'!$A$2:$J$22,9,FALSE),"") | K45: =IFERROR(D45*VLOOKUP(A45,'NFI dimensions'!$A$2:$J$22,10,FALSE),"") | L45: =IFERROR(IF($L$12="",0,IF($L$12="Road",H45/1000*750,IF($L$12="Air",H45/1000*2000))),"")
B46: =IFERROR(VLOOKUP(A46,'NFI dimensions'!A8:J28,3,FALSE),"") | E46: =IF(D46="","",IFERROR(D46/VLOOKUP(A46,'NFI dimensions'!$A$2:$J$22,4,0),"")) | H46: =IFERROR(E46*VLOOKUP(A46,'NFI dimensions'!$A$2:$J$22,8,FALSE),"") | I46: =IFERROR(E46*VLOOKUP(A46,'NFI dimensions'!$A$2:$J$22,9,FALSE),"") | K46: =IFERROR(D46*VLOOKUP(A46,'NFI dimensions'!$A$2:$J$22,10,FALSE),"") | L46: =IFERROR(IF($L$12="",0,IF($L$12="Road",H46/1000*750,IF($L$12="Air",H46/1000*2000))),"")
...

Sheet List of Items
A1: Serial | B1: Item Name
A2: NFI001 | B2: Packed standard NFI Kits
A3: NFI002 | B3: Blankets
A4: NFI003 | B4: Kanga
A5: NFI004 | B5: Kitchen Sets
A6: NFI005 | B6: Mosquito Nets
A7: NFI006 | B7: Sleeping Mats
A8: SNFI001 | B8: Plastic sheeting
A9: NFI007 | B9: Solar Lamp
A10: NFI008 | B10: NFI bag
A11: SK001 | B11: Survival Kits
A12: SK002 | B12: HEB (BP5) Biscuits
... A21: SHEL009 | B21: Rubber Rope

Sheet NFI dimensions
A1: Item Name | B1: Item Category | C1: Serial | D1: Packaging Unit | E1: LENGTH /cm | F1: WIDTH/ cm | G1: HEIGHT /cm | H1: WEIGHT/ Kg | I1: VOLUME /M3 | J1: Price
A2: Packed standard NFI Kits | B2: NFI | C2: NFI001 | D2: 1 | E2: 96 | F2: 96 | G2: 25 | H2: 13 | I2: 0.075 | J2: 44.72
A3: Blankets | B3: NFI | C3: NFI002 | D3: 50 | E3: 68 | F3: 50 | G3: 40 | H3: 51 | I3: 0.136 | J3: 2.73
A4: Kanga | B4: NFI | C4: NFI003 | D4: 200 | E4: 120 | F4: 40 | G4: 30 | H4: 88.4 | I4: 0.144 | J4: 2.29
A5: Kitchen Sets | B5: NFI | C5: NFI004 | D5: 4 | E5: 55 | F5: 30 | G5: 34 | H5: 16.4 | I5: 0.0561 | J5: 12
A6: Mosquito Nets | B6: NFI | C6: NFI005 | D6: 50 | E6: 63 | F6: 40 | G6: 30 | H6: 22.5 | I6: 0.0756 | J6: 1.82
A7: Sleeping Mats | B7: NFI | C7: NFI006 | D7: 50 | E7: 95 | F7: 54 | G7: 50 | H7: 43 | I7: 0.2565 | J7: 2.3
A8: Plastic Sheet | B8: NFI | C8: SNFI001 | D8: 5 | E8: 63 | F8: 46 | G8: 18 | H8: 22.8 | I8: 0.052164 | J8: 12.59
A9: Solar Lamp | B9: NFI | C9: NFI007 | D9: 50 | E9: 61 | F9: 22 | G9: 26 | H9: 10 | I9: 0.034892 | J9: 5
A10: NFI bag | B10: NFI | C10: NFI008 | D10: 50 | E10: 55 | F10: 55 | G10: 25 | H10: 27 | I10: 0.075625 | J10: 1.85
A11: Survival Kits | B11: Survival kits | C11: SK001 | D11: 1 | E11: 0 | F11: 0 | G11: 0 | H11: 4.2 | I11: 0.045 | J11: 20
A12: HEB (BP5) Biscuits | B12: Survival kits | C12: SK002 | D12: 24 | E12: 0 | F12: 0 | G12: 0 | H12: =0.5*24 -> 12
A13: Plastic Sheet | B13: Shelter | C13: SHEL001
A14: Bamboo Bundles (10) | B14: Shelter | C14: SHEL002 | D14: 1 | E14: 400 | F14: 20 | G14: 20 | H14: 15 | I14: 0.16 | J14: 4.5
A15: Wooden poles | B15: Shelter | C15: SHEL003 | D15: 1 | E15: 4 | F15: 0 | G15: 0 | H15: 15 | I15: 0.043 | J15: 6
A16: Sand Bags | B16: Shelter | C16: SHEL004 | D16: 1000 | E16: 70 | F16: 50 | G16: 30 | H16: 42.5 | I16: 0.105 | J16: 0.77
A17: Family Tents | B17: Shelter | C17: SHEL005 | D17: 1 | E17: 0 | F17: 0 | G17: 0 | H17: 0 | I17: 0 | J17: 457
A18: Tent (6m x 12m) | B18: Shelter | C18: SHEL006 | D18: 1 | E18: 0 | F18: 0 | G18: 0 | H18: 0 | I18: 0 | J18: 457
A19: Nylon Rope (30m) | B19: Shelter | C19: SHEL007 | D19: 70 | E19: 100 | F19: 60 | G19: 20 | H19: 52.3 | I19: 0.12 | J19: 5
A20: Pegs | B20: Shelter | C20: SHEL008 | D20: 6 | E20: 40 | F20: 11 | G20: 6 | H20: 2.8 | I20: 0.00264 | J20: 1
A21: Grub Hoe | B21: Shelter | C21: SHEL009 | D21: 1 | E21: 0 | F21: 0 | G21: 0 | H21: 0 | I21: 0 | J21: 5
A22: Rubber Rope | B22: Shelter | C22: SHEL010 | D22: 100 | E22: 90 | F22: 40 | G22: 30 | H22: 27 | I22: 0.108 | J22: 4.5

Sheet Dropdown_list
A1: Purpose of Request | C1: means of Transport | F1: CRP Partners | G1: Implementing Partners | I1: Yes | J1: State | K1: State Code | M1: State | N1: County | O1: County Code | Q1: Assessment done
A2: Prepositioning | C2: Road | F2: ACT/LWF | G2: AAHI | I2: No | J2: Central Equatoria | K2: 92 | M2: Abyei Admin. Area | N2: Abyei Admin. Area | O2: 9901 | Q2: Yes
A3: Immediate Distribution | C3: Air | F3: CCOSS | G3: Across | J3: Eastern Equatoria | K3: 93 | M3: Central Equatoria | N3: Juba | O3: 9202 | Q3: No
F4: CORDAID | G4: ACTED | J4: Jonglei | K4: 72 | M4: Central Equatoria | N4: Kajo-keji | O4: 9206
F5: Concern Worldwide | G5: ACF-USA | J5: Lakes | K5: 84 | M5: Central Equatoria | N5: Lainya | O5: 9203
F6: DRC | G6: ADRA | J6: Northern Bahr el Ghazal | K6: 82 | M6: Central Equatoria | N6: Morobo | O6: 9205
F7: HDC | G7: AHA | J7: Unity | K7: 73 | M7: Central Equatoria | N7: Terekeka | O7: 9201
F8: INTERSOS | G8: ARC | J8: Upper Nile | K8: 71 | M8: Central Equatoria | N8: Yei | O8: 9204
F9: IOM | G9: AARJ | J9: Warrap | K9: 81 | M9: Eastern Equatoria | N9: Budi | O9: 9306
F10: LCED | G10: AVSI | J10: Western Bahr el Ghazal | K10: 83 | M10: Eastern Equatoria | N10: Ikotos | O10: 9307
F11: MEDAIR | G11: AVSI | J11: Western Equatoria | K11: 91 | M11: Eastern Equatoria | N11: Kapoeta East | O11: 9304
F12: NRC | G12: AWODA | J12: Abyei Admin. Area | K12: 99 | M12: Eastern Equatoria | N12: Kapoeta North | O12: 9303
F13: PAH | G13: Brac | M13: Eastern Equatoria | N13: Kapoeta South | O13: 9305
F14: Plan | G14: CAD | M14: Eastern Equatoria | N14: Lapon | O14: 9302
F15: SSUDA | G15: CADA | M15: Eastern Equatoria | N15: Magwi | O15: 9308
F16: UNHCR | G16: CCOASS | M16: Eastern Equatoria | N16: Torit | O16: 9301
F17: WV South Sudan | G17: CARE | M17: Jonglei | N17: Akobo | O17: 7207
G18: Caritas | M18: Jonglei | N18: Ayod | O18: 7203
G19: CRS | M19: Jonglei | N19: Bor South | O19: 7211
G20: CCM | M20: Jonglei | N20: Canal (Khor Fulus) | O20: 7202
G21: CESVI | M21: Jonglei | N21: Duk | O21: 7204
G22: CMD | M22: Jonglei | N22: Fangak | O22: 7201
G23: CMA | M23: Jonglei | N23: Nyirol | O23: 7206
G24: CMI | M24: Jonglei | N24: Pibor | O24: 7209
G25: Concern | M25: Jonglei | N25: Pochalla | O25: 7208
G26: CCC | M26: Jonglei | N26: Twic East | O26: 7210
G27: COSV | M27: Jonglei | N27: Uror | O27: 7205
G28: CUAMM | M28: Lakes | N28: Awerial | O28: 8408
G29: DCA | M29: Lakes | N29: Cueibet | O29: 8401
... G80: PIN | M80: Western Equatoria | N80: Yambio | O80: 9105
G81: Plan
G82: RI
G83: SP
G84: SCI
G85: SMC
G86: Sobat
G87: SI
G88: SSRC
G89: SSUDA
G90: SPEDP
...
